Workbook

Sheet Dinamica
A1: TIPO DEVEDOR | B1: (Vários itens)
A2: RP | B2: (Tudo)
A4: Rótulos de Linha
A5: 2024
A6: 0000779-62.2024.5.19.0000
A7: 0000970-10.2024.5.19.0000
A8: 0001028-13.2024.5.19.0000
A9: 0003016-69.2024.5.19.0000
A10: 2025
A11: 0000153-09.2025.5.19.0000
A12: 0000161-83.2025.5.19.0000
A13: 0000169-60.2025.5.19.0000
A14: 0000194-73.2025.5.19.0000
A15: 0000203-35.2025.5.19.0000
... A250: Total Geral

Sheet Base de Dados
A1: ID | B1: RP | D1: Nº PROCESSO | E1: Nº RPV/PRECATORIO | F1: VARA | G1: BENEFICIÁRIOS | H1: DEVEDOR | I1: TIPO DEVEDOR | J1: TIPO DE RP | K1: ATUAÇÃO | L1: ANO ATUAÇÃO | M1: ULT. ATUALIZA | N1: REGIME | O1: PRAZO | P1: APRESENTAÇÃO
A2: 9181 | B2: 01372/2023 | C2: =VLOOKUP(B2,Vencidos!$A$2:$B$5409,2,0) -> #N/A | D2: 0000235-39.2022.5.19.0002 | F2: 3ª VARA DO TRABALHO DE MACEIÓ | G2: ROSILENE ALVES DOS SANTOS | H2: UNIÃO FEDERAL (AGU) | I2: FEDERAL | J2: RPV | K2: =VLOOKUP(B2,Relatório!$A$2:$R$420,6,0) -> 04/08/2023 | L2: =RIGHT(K2,4) -> 2023 | M2: =VLOOKUP(B2,Relatório!$A$2:$R$420,9,0) -> 4241.88 | N2: =VLOOKUP(B2,Relatório!$A$2:$R$420,13,0) -> GERAL | O2: =VLOOKUP(B2,Relatório!$A$2:$R$420,17,0) -> No Prazo
A3: 9181 | B3: 01372/2023 | C3: =VLOOKUP(B3,Vencidos!$A$2:$B$5409,2,0) -> #N/A | D3: 0000235-39.2022.5.19.0002 | F3: 3ª VARA DO TRABALHO DE MACEIÓ | G3: IVAN BERGSON VAZ DE OLIVEIRA | H3: UNIÃO FEDERAL (AGU) | I3: FEDERAL | J3: RPV | K3: =VLOOKUP(B3,Relatório!$A$2:$R$420,6,0) -> 04/08/2023 | L3: =RIGHT(K3,4) -> 2023 | N3: =VLOOKUP(B3,Relatório!$A$2:$R$420,13,0) -> GERAL | O3: =VLOOKUP(B3,Relatório!$A$2:$R$420,17,0) -> No Prazo
A4: 9428 | B4: 02534/2024 | C4: =VLOOKUP(B4,Vencidos!$A$2:$B$5409,2,0) -> #N/A | D4: 0060300-21.1990.5.19.0002 | E4: 0002621-77.2024.5.19.0000 | F4: 2ª VARA DO TRABALHO DE MACEIÓ | G4: EDVALDO SANTOS | H4: UNIÃO FEDERAL (AGU) | I4: FEDERAL | J4: RPV | K4: =VLOOKUP(B4,Relatório!$A$2:$R$420,6,0) -> 08/05/2024 | L4: =RIGHT(K4,4) -> 2024 | M4: =VLOOKUP(B4,Relatório!$A$2:$R$420,9,0) -> 8189.74 | N4: =VLOOKUP(B4,Relatório!$A$2:$R$420,13,0) -> GERAL | O4: =VLOOKUP(B4,Relatório!$A$2:$R$420,17,0) -> No Prazo
A5: 9429 | B5: 02536/2024 | C5: =VLOOKUP(B5,Vencidos!$A$2:$B$5409,2,0) -> #N/A | D5: 0060300-21.1990.5.19.0002 | E5: 0002622-62.2024.5.19.0000 | F5: 2ª VARA DO TRABALHO DE MACEIÓ | G5: EVALDO ARAUJO | H5: UNIÃO FEDERAL (AGU) | I5: FEDERAL | J5: RPV | K5: =VLOOKUP(B5,Relatório!$A$2:$R$420,6,0) -> 08/05/2024 | L5: =RIGHT(K5,4) -> 2024 | M5: =VLOOKUP(B5,Relatório!$A$2:$R$420,9,0) -> 69441.85 | N5: =VLOOKUP(B5,Relatório!$A$2:$R$420,13,0) -> GERAL | O5: =VLOOKUP(B5,Relatório!$A$2:$R$420,17,0) -> No Prazo
A6: 9430 | B6: 02537/2024 | C6: =VLOOKUP(B6,Vencidos!$A$2:$B$5409,2,0) -> #N/A | D6: 0060300-21.1990.5.19.0002 | E6: 0002623-47.2024.5.19.0000 | F6: 2ª VARA DO TRABALHO DE MACEIÓ | G6: FERNANDO SANTOS DA ROCHA | H6: UNIÃO FEDERAL (AGU) | I6: FEDERAL | J6: RPV | K6: =VLOOKUP(B6,Relatório!$A$2:$R$420,6,0) -> 08/05/2024 | L6: =RIGHT(K6,4) -> 2024 | M6: =VLOOKUP(B6,Relatório!$A$2:$R$420,9,0) -> 30565.07 | N6: =VLOOKUP(B6,Relatório!$A$2:$R$420,13,0) -> GERAL | O6: =VLOOKUP(B6,Relatório!$A$2:$R$420,17,0) -> No Prazo
A7: 9434 | B7: 02541/2024 | C7: =VLOOKUP(B7,Vencidos!$A$2:$B$5409,2,0) -> #N/A | D7: 0060300-21.1990.5.19.0002 | E7: 0002628-69.2024.5.19.0000 | F7: 2ª VARA DO TRABALHO DE MACEIÓ | G7: CARLOS AUGUSTO CANUTO DA SILVA | H7: UNIÃO FEDERAL (AGU) | I7: FEDERAL | J7: RPV | K7: =VLOOKUP(B7,Relatório!$A$2:$R$420,6,0) -> 08/05/2024 | L7: =RIGHT(K7,4) -> 2024 | M7: =VLOOKUP(B7,Relatório!$A$2:$R$420,9,0) -> 28587.58 | N7: =VLOOKUP(B7,Relatório!$A$2:$R$420,13,0) -> GERAL | O7: =VLOOKUP(B7,Relatório!$A$2:$R$420,17,0) -> No Prazo
A8: 9436 | B8: 02542/2024 | C8: =VLOOKUP(B8,Vencidos!$A$2:$B$5409,2,0) -> #N/A | D8: 0060300-21.1990.5.19.0002 | E8: 0002629-54.2024.5.19.0000 | F8: 2ª VARA DO TRABALHO DE MACEIÓ | G8: ANTONIA MARIA COSTA DOS SANTOS | H8: UNIÃO FEDERAL (AGU) | I8: FEDERAL | J8: RPV | K8: =VLOOKUP(B8,Relatório!$A$2:$R$420,6,0) -> 08/05/2024 | L8: =RIGHT(K8,4) -> 2024 | M8: =VLOOKUP(B8,Relatório!$A$2:$R$420,9,0) -> 22801.22 | N8: =VLOOKUP(B8,Relatório!$A$2:$R$420,13,0) -> GERAL | O8: =VLOOKUP(B8,Relatório!$A$2:$R$420,17,0) -> No Prazo
A9: 9437 | B9: 02543/2024 | C9: =VLOOKUP(B9,Vencidos!$A$2:$B$5409,2,0) -> #N/A | D9: 0060300-21.1990.5.19.0002 | E9: 0002630-39.2024.5.19.0000 | F9: 2ª VARA DO TRABALHO DE MACEIÓ | G9: JOSE SISINANDO SANTIAGO COSTA | H9: UNIÃO FEDERAL (AGU) | I9: FEDERAL | J9: RPV | K9: =VLOOKUP(B9,Relatório!$A$2:$R$420,6,0) -> 08/05/2024 | L9: =RIGHT(K9,4) -> 2024 | M9: =VLOOKUP(B9,Relatório!$A$2:$R$420,9,0) -> 39034.88 | N9: =VLOOKUP(B9,Relatório!$A$2:$R$420,13,0) -> GERAL | O9: =VLOOKUP(B9,Relatório!$A$2:$R$420,17,0) -> No Prazo
A10: 9440 | B10: 02545/2024 | C10: =VLOOKUP(B10,Vencidos!$A$2:$B$5409,2,0) -> #N/A | D10: 0060300-21.1990.5.19.0002 | E10: 0002632-09.2024.5.19.0000 | F10: 2ª VARA DO TRABALHO DE MACEIÓ | G10: MARIA DE LOURDES PAULA | H10: UNIÃO FEDERAL (AGU) | I10: FEDERAL | J10: RPV | K10: =VLOOKUP(B10,Relatório!$A$2:$R$420,6,0) -> 08/05/2024 | L10: =RIGHT(K10,4) -> 2024 | M10: =VLOOKUP(B10,Relatório!$A$2:$R$420,9,0) -> 2361.69 | N10: =VLOOKUP(B10,Relatório!$A$2:$R$420,13,0) -> GERAL | O10: =VLOOKUP(B10,Relatório!$A$2:$R$420,17,0) -> No Prazo
A11: 10195 | B11: 00445/2024 | C11: =VLOOKUP(B11,Vencidos!$A$2:$B$5409,2,0) -> #N/A | D11: 0000235-69.2021.5.19.0262 | E11: 0000779-62.2024.5.19.0000 | F11: 2ª VARA DO TRABALHO DE SÃO MIGUEL DOS CAMPOS | G11: ANTONIO ANANIAS DO NASCIMENTO | H11: JEQUIA DA PRAIA | I11: MUNICIPIOS | J11: Precatório | K11: =VLOOKUP(B11,Relatório!$A$2:$R$420,6,0) -> 19/03/2024 | L11: =RIGHT(K11,4) -> 2024 | M11: =VLOOKUP(B11,Relatório!$A$2:$R$420,9,0) -> 21016.62 | N11: =VLOOKUP(B11,Relatório!$A$2:$R$420,13,0) -> GERAL | O11: =VLOOKUP(B11,Relatório!$A$2:$R$420,17,0) -> No Prazo
A12: 10227 | B12: 02977/2024 | C12: =VLOOKUP(B12,Vencidos!$A$2:$B$5409,2,0) -> #N/A | D12: 0000700-10.2011.5.19.0010 | E12: 0002805-33.2024.5.19.0000 | F12: 11ª VARA DO TRABALHO DE MACEIÓ | G12: JOSE LUIZ DE ALMEIDA | H12: UNIÃO FEDERAL (AGU) | I12: FEDERAL | J12: RPV | K12: =VLOOKUP(B12,Relatório!$A$2:$R$420,6,0) -> 02/09/2024 | L12: =RIGHT(K12,4) -> 2024 | M12: =VLOOKUP(B12,Relatório!$A$2:$R$420,9,0) -> 19289.74 | N12: =VLOOKUP(B12,Relatório!$A$2:$R$420,13,0) -> GERAL | O12: =VLOOKUP(B12,Relatório!$A$2:$R$420,17,0) -> No Prazo
A13: 10349 | B13: 00246/2024 | C13: =VLOOKUP(B13,Vencidos!$A$2:$B$5409,2,0) -> #N/A | D13: 0000610-60.2015.5.19.0010 | E13: 0000686-02.2024.5.19.0000 | F13: 10ª VARA DO TRABALHO DE MACEIÓ | G13: WAGNER BATISTA SANTOS | H13: UNIÃO FEDERAL (AGU) | I13: FEDERAL | J13: RPV | K13: =VLOOKUP(B13,Relatório!$A$2:$R$420,6,0) -> 08/03/2024 | L13: =RIGHT(K13,4) -> 2024 | M13: =VLOOKUP(B13,Relatório!$A$2:$R$420,9,0) -> 2893.77 | N13: =VLOOKUP(B13,Relatório!$A$2:$R$420,13,0) -> GERAL | O13: =VLOOKUP(B13,Relatório!$A$2:$R$420,17,0) -> No Prazo
A14: 10765 | B14: 02181/2023 | C14: =VLOOKUP(B14,Vencidos!$A$2:$B$5409,2,0) -> #N/A | D14: 0000443-14.2013.5.19.0010 | E14: 0001650-29.2023.5.19.0000 | F14: 10ª VARA DO TRABALHO DE MACEIÓ | G14: ANDERSON CASSIANO DOS SANTOS | H14: UNIÃO FEDERAL (AGU) | I14: FEDERAL | J14: RPV | K14: =VLOOKUP(B14,Relatório!$A$2:$R$420,6,0) -> 01/12/2023 | L14: =RIGHT(K14,4) -> 2023 | M14: =VLOOKUP(B14,Relatório!$A$2:$R$420,9,0) -> 7363.64 | N14: =VLOOKUP(B14,Relatório!$A$2:$R$420,13,0) -> GERAL | O14: =VLOOKUP(B14,Relatório!$A$2:$R$420,17,0) -> No Prazo
A15: 11257 | B15: 00869/2024 | C15: =VLOOKUP(B15,Vencidos!$A$2:$B$5409,2,0) -> #N/A | D15: 0000387-18.2021.5.19.0004 | E15: 0001028-13.2024.5.19.0000 | F15: 4ª VARA DO TRABALHO DE MACEIÓ | G15: FERNANDO JACKSON DOS REIS PINTO | H15: JEQUIA DA PRAIA | I15: MUNICIPIOS | J15: Precatório | K15: =VLOOKUP(B15,Relatório!$A$2:$R$420,6,0) -> 01/04/2024 | L15: =RIGHT(K15,4) -> 2024 | M15: =VLOOKUP(B15,Relatório!$A$2:$R$420,9,0) -> 19047.47 | N15: =VLOOKUP(B15,Relatório!$A$2:$R$420,13,0) -> GERAL | O15: =VLOOKUP(B15,Relatório!$A$2:$R$420,17,0) -> No Prazo
A16: 11257 | B16: 00869/2024 | C16: =VLOOKUP(B16,Vencidos!$A$2:$B$5409,2,0) -> #N/A | D16: 0000387-18.2021.5.19.0004 | E16: 0001028-13.2024.5.19.0000 | F16: 4ª VARA DO TRABALHO DE MACEIÓ | G16: EDVILSON LIMA COELHO | H16: JEQUIA DA PRAIA | I16: MUNICIPIOS | J16: Precatório | K16: =VLOOKUP(B16,Relatório!$A$2:$R$420,6,0) -> 01/04/2024 | L16: =RIGHT(K16,4) -> 2024 | N16: =VLOOKUP(B16,Relatório!$A$2:$R$420,13,0) -> GERAL | O16: =VLOOKUP(B16,Relatório!$A$2:$R$420,17,0) -> No Prazo
A17: 10888 | B17: 00635/2024 | C17: =VLOOKUP(B17,Vencidos!$A$2:$B$5409,2,0) -> #N/A | D17: 0000344-82.2022.5.19.0057 | E17: 0000970-10.2024.5.19.0000 | F17: VARA DO TRABALHO DE PORTO CALVO | G17: VANILMA DA SILVA MELO | H17: PORTO CALVO | I17: MUNICIPIOS | J17: Precatório | K17: =VLOOKUP(B17,Relatório!$A$2:$R$420,6,0) -> 21/03/2024 | L17: =RIGHT(K17,4) -> 2024 | M17: =VLOOKUP(B17,Relatório!$A$2:$R$420,9,0) -> 11768.07 | N17: =VLOOKUP(B17,Relatório!$A$2:$R$420,13,0) -> GERAL | O17: =VLOOKUP(B17,Relatório!$A$2:$R$420,17,0) -> No Prazo
A18: 12327 | B18: 00043/2024 | C18: =VLOOKUP(B18,Vencidos!$A$2:$B$5409,2,0) -> #N/A | D18: 0000832-39.2021.5.19.0003 | E18: 0000595-09.2024.5.19.0000 | F18: 3ª VARA DO TRABALHO DE MACEIÓ | G18: ANTONIO SALGUEIRO SOCIEDADE INDIVIDUAL DE ADVOCACIA | H18: UNIÃO FEDERAL (AGU) | I18: FEDERAL | J18: RPV | K18: =VLOOKUP(B18,Relatório!$A$2:$R$420,6,0) -> 07/02/2024 | L18: =RIGHT(K18,4) -> 2024 | M18: =VLOOKUP(B18,Relatório!$A$2:$R$420,9,0) -> 10082.95 | N18: =VLOOKUP(B18,Relatório!$A$2:$R$420,13,0) -> GERAL | O18: =VLOOKUP(B18,Relatório!$A$2:$R$420,17,0) -> No Prazo
A19: 12327 | B19: 00043/2024 | C19: =VLOOKUP(B19,Vencidos!$A$2:$B$5409,2,0) -> #N/A | D19: 0000832-39.2021.5.19.0003 | E19: 0000595-09.2024.5.19.0000 | F19: 3ª VARA DO TRABALHO DE MACEIÓ | G19: HELENO SANTOS DA SILVA | H19: UNIÃO FEDERAL (AGU) | I19: FEDERAL | J19: RPV | K19: =VLOOKUP(B19,Relatório!$A$2:$R$420,6,0) -> 07/02/2024 | L19: =RIGHT(K19,4) -> 2024 | N19: =VLOOKUP(B19,Relatório!$A$2:$R$420,13,0) -> GERAL | O19: =VLOOKUP(B19,Relatório!$A$2:$R$420,17,0) -> No Prazo
A20: 12328 | B20: 00042/2024 | C20: =VLOOKUP(B20,Vencidos!$A$2:$B$5409,2,0) -> #N/A | D20: 0000436-14.2011.5.19.0003 | E20: 0000594-24.2024.5.19.0000 | F20: 3ª VARA DO TRABALHO DE MACEIÓ | G20: DANIELLA SILVA DOS SANTOS | H20: UNIÃO FEDERAL (AGU) | I20: FEDERAL | J20: RPV | K20: =VLOOKUP(B20,Relatório!$A$2:$R$420,6,0) -> 07/02/2024 | L20: =RIGHT(K20,4) -> 2024 | M20: =VLOOKUP(B20,Relatório!$A$2:$R$420,9,0) -> 11332.93 | N20: =VLOOKUP(B20,Relatório!$A$2:$R$420,13,0) -> GERAL | O20: =VLOOKUP(B20,Relatório!$A$2:$R$420,17,0) -> No Prazo
A21: 13010 | B21: 02763/2024 | C21: =VLOOKUP(B21,Vencidos!$A$2:$B$5409,2,0) -> #N/A | D21: 0001006-32.2018.5.19.0010 | E21: 0002715-25.2024.5.19.0000 | F21: 10ª VARA DO TRABALHO DE MACEIÓ | G21: ANDREA LUZIA CAVALCANTI DE ARRUDA COUTINHO | H21: UNIÃO FEDERAL (AGU) | I21: FEDERAL | J21: RPV | K21: =VLOOKUP(B21,Relatório!$A$2:$R$420,6,0) -> 09/07/2024 | L21: =RIGHT(K21,4) -> 2024 | M21: =VLOOKUP(B21,Relatório!$A$2:$R$420,9,0) -> 443.57 | N21: =VLOOKUP(B21,Relatório!$A$2:$R$420,13,0) -> GERAL | O21: =VLOOKUP(B21,Relatório!$A$2:$R$420,17,0) -> No Prazo
A22: 12997 | B22: 03155/2024 | C22: =VLOOKUP(B22,Vencidos!$A$2:$B$5409,2,0) -> #N/A | D22: 0000439-02.2021.5.19.0008 | E22: 0002921-39.2024.5.19.0000 | F22: 3ª VARA DO TRABALHO DE MACEIÓ | G22: ABELARDO FARIAS DOS SANTOS | H22: UNIÃO FEDERAL (AGU) | I22: FEDERAL | J22: RPV | K22: =VLOOKUP(B22,Relatório!$A$2:$R$420,6,0) -> 18/11/2024 | L22: =RIGHT(K22,4) -> 2024 | M22: =VLOOKUP(B22,Relatório!$A$2:$R$420,9,0) -> 81324.13 | N22: =VLOOKUP(B22,Relatório!$A$2:$R$420,13,0) -> GERAL | O22: =VLOOKUP(B22,Relatório!$A$2:$R$420,17,0) -> No Prazo
A23: 12997 | B23: 03155/2024 | C23: =VLOOKUP(B23,Vencidos!$A$2:$B$5409,2,0) -> #N/A | D23: 0000439-02.2021.5.19.0008 | E23: 0002921-39.2024.5.19.0000 | F23: 3ª VARA DO TRABALHO DE MACEIÓ | G23: Luiz Virginio Sociedade de Advogados | H23: UNIÃO FEDERAL (AGU) | I23: FEDERAL | J23: RPV | K23: =VLOOKUP(B23,Relatório!$A$2:$R$420,6,0) -> 18/11/2024 | L23: =RIGHT(K23,4) -> 2024 | N23: =VLOOKUP(B23,Relatório!$A$2:$R$420,13,0) -> GERAL | O23: =VLOOKUP(B23,Relatório!$A$2:$R$420,17,0) -> No Prazo
A24: 12997 | B24: 03155/2024 | C24: =VLOOKUP(B24,Vencidos!$A$2:$B$5409,2,0) -> #N/A | D24: 0000439-02.2021.5.19.0008 | E24: 0002921-39.2024.5.19.0000 | F24: 3ª VARA DO TRABALHO DE MACEIÓ | G24: MARIA DA CONCEIÇÃO SANTOS FARIAS | H24: UNIÃO FEDERAL (AGU) | I24: FEDERAL | J24: RPV | K24: =VLOOKUP(B24,Relatório!$A$2:$R$420,6,0) -> 18/11/2024 | L24: =RIGHT(K24,4) -> 2024 | N24: =VLOOKUP(B24,Relatório!$A$2:$R$420,13,0) -> GERAL | O24: =VLOOKUP(B24,Relatório!$A$2:$R$420,17,0) -> No Prazo
A25: 12968 | B25: 03158/2024 | C25: =VLOOKUP(B25,Vencidos!$A$2:$B$5409,2,0) -> #N/A | D25: 0000439-02.2021.5.19.0008 | E25: 0002924-91.2024.5.19.0000 | F25: 3ª VARA DO TRABALHO DE MACEIÓ | G25: LEONARDO MOTENEGRO DUQUE DE SOUZA | H25: UNIÃO FEDERAL (AGU) | I25: FEDERAL | J25: RPV | K25: =VLOOKUP(B25,Relatório!$A$2:$R$420,6,0) -> 18/11/2024 | L25: =RIGHT(K25,4) -> 2024 | M25: =VLOOKUP(B25,Relatório!$A$2:$R$420,9,0) -> 79577 | N25: =VLOOKUP(B25,Relatório!$A$2:$R$420,13,0) -> GERAL | O25: =VLOOKUP(B25,Relatório!$A$2:$R$420,17,0) -> No Prazo
A26: 12963 | B26: 03156/2024 | C26: =VLOOKUP(B26,Vencidos!$A$2:$B$5409,2,0) -> #N/A | D26: 0000439-02.2021.5.19.0008 | E26: 0002922-24.2024.5.19.0000 | F26: 3ª VARA DO TRABALHO DE MACEIÓ | G26: ANDRADE LIMA ADVOCACIA | H26: UNIÃO FEDERAL (AGU) | I26: FEDERAL | J26: RPV | K26: =VLOOKUP(B26,Relatório!$A$2:$R$420,6,0) -> 18/11/2024 | L26: =RIGHT(K26,4) -> 2024 | M26: =VLOOKUP(B26,Relatório!$A$2:$R$420,9,0) -> 81324.08 | N26: =VLOOKUP(B26,Relatório!$A$2:$R$420,13,0) -> GERAL | O26: =VLOOKUP(B26,Relatório!$A$2:$R$420,17,0) -> No Prazo
A27: 12963 | B27: 03156/2024 | C27: =VLOOKUP(B27,Vencidos!$A$2:$B$5409,2,0) -> #N/A | D27: 0000439-02.2021.5.19.0008 | E27: 0002922-24.2024.5.19.0000 | F27: 3ª VARA DO TRABALHO DE MACEIÓ | G27: NILVAN BENEDITO OLIVIERA SANTOS | H27: UNIÃO FEDERAL (AGU) | I27: FEDERAL | J27: RPV | K27: =VLOOKUP(B27,Relatório!$A$2:$R$420,6,0) -> 18/11/2024 | L27: =RIGHT(K27,4) -> 2024 | N27: =VLOOKUP(B27,Relatório!$A$2:$R$420,13,0) -> GERAL | O27: =VLOOKUP(B27,Relatório!$A$2:$R$420,17,0) -> No Prazo
A28: 12963 | B28: 03156/2024 | C28: =VLOOKUP(B28,Vencidos!$A$2:$B$5409,2,0) -> #N/A | D28: 0000439-02.2021.5.19.0008 | E28: 0002922-24.2024.5.19.0000 | F28: 3ª VARA DO TRABALHO DE MACEIÓ | G28: MARIA DE FATIMA ANDRADE SANTOS | H28: UNIÃO FEDERAL (AGU) | I28: FEDERAL | J28: RPV | K28: =VLOOKUP(B28,Relatório!$A$2:$R$420,6,0) -> 18/11/2024 | L28: =RIGHT(K28,4) -> 2024 | N28: =VLOOKUP(B28,Relatório!$A$2:$R$420,13,0) -> GERAL | O28: =VLOOKUP(B28,Relatório!$A$2:$R$420,17,0) -> No Prazo
A29: 12757 | B29: 03157/2024 | C29: =VLOOKUP(B29,Vencidos!$A$2:$B$5409,2,0) -> #N/A | D29: 0000439-02.2021.5.19.0008 | E29: 0002923-09.2024.5.19.0000 | F29: 3ª VARA DO TRABALHO DE MACEIÓ | G29: MARIA SELMA DA SILVA | H29: UNIÃO FEDERAL (AGU) | I29: FEDERAL | J29: RPV | K29: =VLOOKUP(B29,Relatório!$A$2:$R$420,6,0) -> 18/11/2024 | L29: =RIGHT(K29,4) -> 2024 | M29: =VLOOKUP(B29,Relatório!$A$2:$R$420,9,0) -> 75593.99 | N29: =VLOOKUP(B29,Relatório!$A$2:$R$420,13,0) -> GERAL | O29: =VLOOKUP(B29,Relatório!$A$2:$R$420,17,0) -> No Prazo
A30: 12757 | B30: 03157/2024 | C30: =VLOOKUP(B30,Vencidos!$A$2:$B$5409,2,0) -> #N/A | D30: 0000439-02.2021.5.19.0008 | E30: 0002923-09.2024.5.19.0000 | F30: 3ª VARA DO TRABALHO DE MACEIÓ | G30: Luiz Virginio Sociedade de Advogados | H30: UNIÃO FEDERAL (AGU) | I30: FEDERAL | J30: RPV | K30: =VLOOKUP(B30,Relatório!$A$2:$R$420,6,0) -> 18/11/2024 | L30: =RIGHT(K30,4) -> 2024 | N30: =VLOOKUP(B30,Relatório!$A$2:$R$420,13,0) -> GERAL | O30: =VLOOKUP(B30,Relatório!$A$2:$R$420,17,0) -> No Prazo
A31: 12757 | B31: 03157/2024 | C31: =VLOOKUP(B31,Vencidos!$A$2:$B$5409,2,0) -> #N/A | D31: 0000439-02.2021.5.19.0008 | E31: 0002923-09.2024.5.19.0000 | F31: 3ª VARA DO TRABALHO DE MACEIÓ | G31: VALMIR LUIZ TORRES TAVARES | H31: UNIÃO FEDERAL (AGU) | I31: FEDERAL | J31: RPV | K31: =VLOOKUP(B31,Relatório!$A$2:$R$420,6,0) -> 18/11/2024 | L31: =RIGHT(K31,4) -> 2024 | N31: =VLOOKUP(B31,Relatório!$A$2:$R$420,13,0) -> GERAL | O31: =VLOOKUP(B31,Relatório!$A$2:$R$420,17,0) -> No Prazo
A32: 12770 | B32: 03154/2024 | C32: =VLOOKUP(B32,Vencidos!$A$2:$B$5409,2,0) -> #N/A | D32: 0000439-02.2021.5.19.0008 | E32: 0002920-54.2024.5.19.0000 | F32: 3ª VARA DO TRABALHO DE MACEIÓ | G32: JESUALDO DIAS DA SILVA | H32: UNIÃO FEDERAL (AGU) | I32: FEDERAL | J32: RPV | K32: =VLOOKUP(B32,Relatório!$A$2:$R$420,6,0) -> 18/11/2024 | L32: =RIGHT(K32,4) -> 2024 | M32: =VLOOKUP(B32,Relatório!$A$2:$R$420,9,0) -> 79986.87 | N32: =VLOOKUP(B32,Relatório!$A$2:$R$420,13,0) -> GERAL | O32: =VLOOKUP(B32,Relatório!$A$2:$R$420,17,0) -> No Prazo
A33: 12770 | B33: 03154/2024 | C33: =VLOOKUP(B33,Vencidos!$A$2:$B$5409,2,0) -> #N/A | D33: 0000439-02.2021.5.19.0008 | E33: 0002920-54.2024.5.19.0000 | F33: 3ª VARA DO TRABALHO DE MACEIÓ | G33: JOSUE DIAS DA SILVA | H33: UNIÃO FEDERAL (AGU) | I33: FEDERAL | J33: RPV | K33: =VLOOKUP(B33,Relatório!$A$2:$R$420,6,0) -> 18/11/2024 | L33: =RIGHT(K33,4) -> 2024 | N33: =VLOOKUP(B33,Relatório!$A$2:$R$420,13,0) -> GERAL | O33: =VLOOKUP(B33,Relatório!$A$2:$R$420,17,0) -> No Prazo
A34: 12770 | B34: 03154/2024 | C34: =VLOOKUP(B34,Vencidos!$A$2:$B$5409,2,0) -> #N/A | D34: 0000439-02.2021.5.19.0008 | E34: 0002920-54.2024.5.19.0000 | F34: 3ª VARA DO TRABALHO DE MACEIÓ | G34: GERALDO DIAS DA SILVA | H34: UNIÃO FEDERAL (AGU) | I34: FEDERAL | J34: RPV | K34: =VLOOKUP(B34,Relatório!$A$2:$R$420,6,0) -> 18/11/2024 | L34: =RIGHT(K34,4) -> 2024 | N34: =VLOOKUP(B34,Relatório!$A$2:$R$420,13,0) -> GERAL | O34: =VLOOKUP(B34,Relatório!$A$2:$R$420,17,0) -> No Prazo
A35: 12770 | B35: 03154/2024 | C35: =VLOOKUP(B35,Vencidos!$A$2:$B$5409,2,0) -> #N/A | D35: 0000439-02.2021.5.19.0008 | E35: 0002920-54.2024.5.19.0000 | F35: 3ª VARA DO TRABALHO DE MACEIÓ | G35: NADJA DIAS DA SILVA | H35: UNIÃO FEDERAL (AGU) | I35: FEDERAL | J35: RPV | K35: =VLOOKUP(B35,Relatório!$A$2:$R$420,6,0) -> 18/11/2024 | L35: =RIGHT(K35,4) -> 2024 | N35: =VLOOKUP(B35,Relatório!$A$2:$R$420,13,0) -> GERAL | O35: =VLOOKUP(B35,Relatório!$A$2:$R$420,17,0) -> No Prazo
A36: 12770 | B36: 03154/2024 | C36: =VLOOKUP(B36,Vencidos!$A$2:$B$5409,2,0) -> #N/A | D36: 0000439-02.2021.5.19.0008 | E36: 0002920-54.2024.5.19.0000 | F36: 3ª VARA DO TRABALHO DE MACEIÓ | G36: NORMA DIAS DA SILVA | H36: UNIÃO FEDERAL (AGU) | I36: FEDERAL | J36: RPV | K36: =VLOOKUP(B36,Relatório!$A$2:$R$420,6,0) -> 18/11/2024 | L36: =RIGHT(K36,4) -> 2024 | N36: =VLOOKUP(B36,Relatório!$A$2:$R$420,13,0) -> GERAL | O36: =VLOOKUP(B36,Relatório!$A$2:$R$420,17,0) -> No Prazo
A37: 12770 | B37: 03154/2024 | C37: =VLOOKUP(B37,Vencidos!$A$2:$B$5409,2,0) -> #N/A | D37: 0000439-02.2021.5.19.0008 | E37: 0002920-54.2024.5.19.0000 | F37: 3ª VARA DO TRABALHO DE MACEIÓ | G37: NIEDJA DIAS DA SILVA | H37: UNIÃO FEDERAL (AGU) | I37: FEDERAL | J37: RPV | K37: =VLOOKUP(B37,Relatório!$A$2:$R$420,6,0) -> 18/11/2024 | L37: =RIGHT(K37,4) -> 2024 | N37: =VLOOKUP(B37,Relatório!$A$2:$R$420,13,0) -> GERAL | O37: =VLOOKUP(B37,Relatório!$A$2:$R$420,17,0) -> No Prazo
A38: 12770 | B38: 03154/2024 | C38: =VLOOKUP(B38,Vencidos!$A$2:$B$5409,2,0) -> #N/A | D38: 0000439-02.2021.5.19.0008 | E38: 0002920-54.2024.5.19.0000 | F38: 3ª VARA DO TRABALHO DE MACEIÓ | G38: NADILMA DIAS DOS SANTOS | H38: UNIÃO FEDERAL (AGU) | I38: FEDERAL | J38: RPV | K38: =VLOOKUP(B38,Relatório!$A$2:$R$420,6,0) -> 18/11/2024 | L38: =RIGHT(K38,4) -> 2024 | N38: =VLOOKUP(B38,Relatório!$A$2:$R$420,13,0) -> GERAL | O38: =VLOOKUP(B38,Relatório!$A$2:$R$420,17,0) -> No Prazo
A39: 12770 | B39: 03154/2024 | C39: =VLOOKUP(B39,Vencidos!$A$2:$B$5409,2,0) -> #N/A | D39: 0000439-02.2021.5.19.0008 | E39: 0002920-54.2024.5.19.0000 | F39: 3ª VARA DO TRABALHO DE MACEIÓ | G39: JAMERSON DIAS DA SILVA | H39: UNIÃO FEDERAL (AGU) | I39: FEDERAL | J39: RPV | K39: =VLOOKUP(B39,Relatório!$A$2:$R$420,6,0) -> 18/11/2024 | L39: =RIGHT(K39,4) -> 2024 | N39: =VLOOKUP(B39,Relatório!$A$2:$R$420,13,0) -> GERAL | O39: =VLOOKUP(B39,Relatório!$A$2:$R$420,17,0) -> No Prazo
A40: 12770 | B40: 03154/2024 | C40: =VLOOKUP(B40,Vencidos!$A$2:$B$5409,2,0) -> #N/A | D40: 0000439-02.2021.5.19.0008 | E40: 0002920-54.2024.5.19.0000 | F40: 3ª VARA DO TRABALHO DE MACEIÓ | G40: ROSEANE DIAS DA SILVA ARAUJO | H40: UNIÃO FEDERAL (AGU) | I40: FEDERAL | J40: RPV | K40: =VLOOKUP(B40,Relatório!$A$2:$R$420,6,0) -> 18/11/2024 | L40: =RIGHT(K40,4) -> 2024 | N40: =VLOOKUP(B40,Relatório!$A$2:$R$420,13,0) -> GERAL | O40: =VLOOKUP(B40,Relatório!$A$2:$R$420,17,0) -> No Prazo
...

Sheet Plan3
A1: Ano de Vencimento | B1: 2025
A2: Esfera | B2: Municipal
A3: Tipo de Requisição | B3: Precatório
A4: Situação da RP | B4: (Tudo)
A6: Rótulos de Linha | B6: Contagem de Nº da RP
A7: AGUA BRANCA | B7: 1
A8: ANADIA | B8: 48
A9: BARRA DE SANTO ANTONIO | B9: 9
A10: BARRA DE SAO MIGUEL | B10: 7
A11: BOCA DA MATA | B11: 1
A12: BRANQUINHA | B12: 2
A13: CAJUEIRO | B13: 1
A14: CANAPI | B14: 4
A15: COITE DO NOIA | B15: 1
A16: DELMIRO GOUVEIA | B16: 2
A17: FEIRA GRANDE | B17: 2
A18: GIRAU DO PONCIANO | B18: 1
... A50: Total Geral | B50: 275

Sheet Vencidos
A1: Nº da RP | B1: Nº do Processo | C1: Precatório/RPV | D1: Tipo de Requisição | E1: Natureza do Crédito | F1: Data da Autuação | G1: Situação da RP | H1: RP Publicada | I1: Valor Atual | J1: Esfera | K1: Ano de Vencimento | L1: Ente Devedor | M1: Entidade Devedora (Executado) | N1: Regime Pagamento | O1: Permite acordo Direto | P1: Vara de Origem | Q1: Possui Convênio | R1: Prazo de Pagamento | S1: Data Fim Prazo de Pagamento
A2: 10007/2020 | B2: 0000407-34.2018.5.19.0062 | C2: - | D2: Precatório | E2: Alimentar | F2: 07/05/2020 | G2: Autuada | H2: Sim | I2: 0 | J2: Municipal | K2: 2021 | L2: BARRA DE SAO MIGUEL | M2: BARRA DE SAO MIGUEL | N2: GERAL | O2: Não | P2: 1ª VARA DO TRABALHO | Q2: Sim | R2: Vencido | S2: -
A3: 10010/2020 | B3: 0131200-92.2005.5.19.0005 | C3: - | D3: Precatório | E3: Alimentar | F3: 07/05/2020 | G3: Cancelada | H3: Sim | I3: 25448.94 | J3: Estadual | K3: 2021 | L3: ALAGOAS | M3: ALAGOAS | N3: GERAL | O3: Não | P3: 5ª VARA DO TRABALHO | Q3: Sim | R3: Vencido | S3: -
A4: 10015/2020 | B4: 0000752-53.2013.5.19.0004 | C4: 0000878-66.2023.5.19.0000 | D4: Precatório | E4: Alimentar | F4: 07/05/2020 | G4: Autuada | H4: Sim | I4: 0 | J4: Municipal | K4: 2021 | L4: MACEIO | M4: MACEIO | N4: ESPECIAL | O4: Sim | P4: 4ª VARA DO TRABALHO | Q4: Sim | R4: Vencido | S4: -
A5: 10146/2020 | B5: 0190200-91.2003.5.19.0005 | C5: - | D5: Precatório | E5: Alimentar | F5: 21/05/2020 | G5: Cancelada | H5: Sim | I5: 22797.83 | J5: Estadual | K5: 2021 | L5: ALAGOAS | M5: UNIVERSIDADE ESTADUAL DE CIENCIAS DA SAUDE DE ALAGOAS - UNCISAL | N5: GERAL | O5: Não | P5: 5ª VARA DO TRABALHO | Q5: Sim | R5: Vencido | S5: -
A6: 10041/2020 | B6: 0000151-57.2019.5.19.0062 | C6: - | D6: Precatório | E6: Alimentar | F6: 08/05/2020 | G6: Autuada | H6: Sim | I6: 0 | J6: Municipal | K6: 2021 | L6: ANADIA | M6: ANADIA | N6: ESPECIAL | O6: Não | P6: 1ª VARA DO TRABALHO | Q6: Sim | R6: Vencido | S6: -
A7: 10043/2020 | B7: 0000312-67.2019.5.19.0062 | C7: - | D7: Precatório | E7: Alimentar | F7: 08/05/2020 | G7: Autuada | H7: Sim | I7: 0 | J7: Municipal | K7: 2021 | L7: ANADIA | M7: ANADIA | N7: ESPECIAL | O7: Não | P7: 1ª VARA DO TRABALHO | Q7: Sim | R7: Vencido | S7: -
A8: 10046/2020 | B8: 0001068-21.2017.5.19.0006 | C8: 0000889-95.2023.5.19.0000 | D8: Precatório | E8: Alimentar | F8: 08/05/2020 | G8: Autuada | H8: Sim | I8: 0 | J8: Municipal | K8: 2021 | L8: MACEIO | M8: MACEIO | N8: ESPECIAL | O8: Sim | P8: 6ª VARA DO TRABALHO | Q8: Sim | R8: Vencido | S8: -
A9: 10047/2020 | B9: 0000920-78.2015.5.19.0006 | C9: - | D9: Precatório | E9: Alimentar | F9: 08/05/2020 | G9: Autuada | H9: Sim | I9: 0 | J9: Federal | K9: 2021 | L9: EMPRESA BRASILEIRA DE CORREIOS E TELEGRAFOS | M9: EMPRESA BRASILEIRA DE CORREIOS E TELEGRAFOS | N9: GERAL | O9: Não | P9: 11ª VARA DO TRABALHO | Q9: Não | R9: Vencido | S9: -
A10: 10076/2020 | B10: 0001102-39.2014.5.19.0058 | C10: - | D10: Precatório | E10: Alimentar | F10: 14/05/2020 | G10: Autuada | H10: Sim | I10: 0 | J10: Municipal | K10: 2021 | L10: MONTEIROPOLIS | M10: MONTEIROPOLIS | N10: GERAL | O10: Não | P10: VARA DO TRABALHO | Q10: Sim | R10: Vencido | S10: -
A11: 00014/2020 | B11: 0001617-69.2017.5.19.0058 | C11: - | D11: RPV | E11: Alimentar | F11: 04/05/2020 | G11: Autuada | H11: Sim | I11: 16003.58 | J11: Municipal | K11: - | L11: PAO DE ACUCAR | M11: PAO DE ACUCAR | N11: GERAL | O11: Não | P11: VARA DO TRABALHO | Q11: Não | R11: Vencido | S11: 15/07/2020
A12: 00015/2020 | B12: 0000958-26.2018.5.19.0058 | C12: - | D12: RPV | E12: Alimentar | F12: 06/05/2020 | G12: Autuada | H12: Sim | I12: 3509.17 | J12: Municipal | K12: - | L12: CARNEIROS | M12: CARNEIROS | N12: GERAL | O12: Não | P12: VARA DO TRABALHO | Q12: Não | R12: Vencido | S12: 20/07/2020
A13: 10147/2020 | B13: 0190200-91.2003.5.19.0005 | C13: - | D13: Precatório | E13: Alimentar | F13: 21/05/2020 | G13: Cancelada | H13: Sim | I13: 22797.83 | J13: Estadual | K13: 2021 | L13: ALAGOAS | M13: UNIVERSIDADE ESTADUAL DE CIENCIAS DA SAUDE DE ALAGOAS - UNCISAL | N13: GERAL | O13: Não | P13: 5ª VARA DO TRABALHO | Q13: Sim | R13: Vencido | S13: -
A14: 10148/2020 | B14: 0190200-91.2003.5.19.0005 | C14: - | D14: Precatório | E14: Alimentar | F14: 21/05/2020 | G14: Cancelada | H14: Sim | I14: 22797.83 | J14: Estadual | K14: 2021 | L14: ALAGOAS | M14: UNIVERSIDADE ESTADUAL DE CIENCIAS DA SAUDE DE ALAGOAS - UNCISAL | N14: GERAL | O14: Não | P14: 5ª VARA DO TRABALHO | Q14: Sim | R14: Vencido | S14: -
A15: 00023/2020 | B15: 0001136-45.2015.5.19.0004 | C15: - | D15: RPV | E15: Alimentar | F15: 07/05/2020 | G15: Cancelada | H15: Não | I15: 3841.67 | J15: Municipal | K15: - | L15: RIO LARGO | M15: RIO LARGO | N15: GERAL | O15: Não | P15: 4ª VARA DO TRABALHO | Q15: Não | R15: Vencido | S15: 19/03/2020
A16: 00026/2020 | B16: 0000558-12.2018.5.19.0058 | C16: - | D16: RPV | E16: Alimentar | F16: 08/05/2020 | G16: Autuada | H16: Sim | I16: 5468.33 | J16: Municipal | K16: - | L16: SANTANA DO IPANEMA | M16: SANTANA DO IPANEMA | N16: GERAL | O16: Não | P16: VARA DO TRABALHO | Q16: Não | R16: Vencido | S16: 21/07/2020
A17: 10068/2020 | B17: 0000057-24.2019.5.19.0058 | C17: - | D17: Precatório | E17: Alimentar | F17: 13/05/2020 | G17: Autuada | H17: Sim | I17: 0 | J17: Municipal | K17: 2021 | L17: DELMIRO GOUVEIA | M17: DELMIRO GOUVEIA | N17: ESPECIAL | O17: Não | P17: VARA DO TRABALHO | Q17: Sim | R17: Vencido | S17: -
A18: 10071/2020 | B18: 0000039-79.2016.5.19.0002 | C18: - | D18: Precatório | E18: Alimentar | F18: 13/05/2020 | G18: Autuada | H18: Sim | I18: 0 | J18: Municipal | K18: 2021 | L18: RIO LARGO | M18: RIO LARGO | N18: GERAL | O18: Não | P18: 2ª VARA DO TRABALHO | Q18: Sim | R18: Vencido | S18: -
A19: 10078/2020 | B19: 0000754-69.2017.5.19.0008 | C19: - | D19: Precatório | E19: Alimentar | F19: 14/05/2020 | G19: Cancelada | H19: Não | I19: 15645.99 | J19: Municipal | K19: 2021 | L19: RIO LARGO | M19: RIO LARGO | N19: GERAL | O19: Não | P19: 9ª VARA DO TRABALHO | Q19: Sim | R19: Vencido | S19: -
A20: 10111/2020 | B20: 0000756-25.2013.5.19.0058 | C20: - | D20: Precatório | E20: Alimentar | F20: 18/05/2020 | G20: Autuada | H20: Sim | I20: 0 | J20: Municipal | K20: 2021 | L20: MARAVILHA | M20: MARAVILHA | N20: GERAL | O20: Não | P20: VARA DO TRABALHO | Q20: Sim | R20: Vencido | S20: -
A21: 10114/2020 | B21: 0000697-95.2017.5.19.0058 | C21: - | D21: Precatório | E21: Alimentar | F21: 18/05/2020 | G21: Autuada | H21: Sim | I21: 0 | J21: Municipal | K21: 2021 | L21: MARAVILHA | M21: MARAVILHA | N21: GERAL | O21: Não | P21: VARA DO TRABALHO | Q21: Sim | R21: Vencido | S21: -
A22: 10115/2020 | B22: 0001367-36.2017.5.19.0058 | C22: - | D22: Precatório | E22: Alimentar | F22: 18/05/2020 | G22: Autuada | H22: Sim | I22: 0 | J22: Municipal | K22: 2021 | L22: OLHO D'AGUA DAS FLORES | M22: OLHO D'AGUA DAS FLORES | N22: GERAL | O22: Não | P22: VARA DO TRABALHO | Q22: Sim | R22: Vencido | S22: -
A23: 10080/2020 | B23: 0000908-26.2013.5.19.0009 | C23: 0000894-20.2023.5.19.0000 | D23: Precatório | E23: Alimentar | F23: 14/05/2020 | G23: Autuada | H23: Sim | I23: 0 | J23: Municipal | K23: 2021 | L23: MACEIO | M23: MACEIO | N23: ESPECIAL | O23: Sim | P23: 9ª VARA DO TRABALHO | Q23: Sim | R23: Vencido | S23: -
A24: 10107/2020 | B24: 0000513-34.2013.5.19.0009 | C24: 0000896-87.2023.5.19.0000 | D24: Precatório | E24: Alimentar | F24: 18/05/2020 | G24: Autuada | H24: Sim | I24: 0 | J24: Municipal | K24: 2021 | L24: MACEIO | M24: MACEIO | N24: ESPECIAL | O24: Sim | P24: 9ª VARA DO TRABALHO | Q24: Sim | R24: Vencido | S24: -
A25: 10083/2020 | B25: 0000100-29.2017.5.19.0058 | C25: - | D25: Precatório | E25: Alimentar | F25: 14/05/2020 | G25: Autuada | H25: Sim | I25: 0 | J25: Municipal | K25: 2021 | L25: PARICONHA | M25: PARICONHA | N25: GERAL | O25: Não | P25: VARA DO TRABALHO | Q25: Sim | R25: Vencido | S25: -
A26: 10092/2020 | B26: 0001505-03.2017.5.19.0058 | C26: - | D26: Precatório | E26: Alimentar | F26: 15/05/2020 | G26: Autuada | H26: Sim | I26: 0 | J26: Municipal | K26: 2021 | L26: PARICONHA | M26: PARICONHA | N26: GERAL | O26: Não | P26: VARA DO TRABALHO | Q26: Sim | R26: Vencido | S26: -
A27: 10134/2020 | B27: 0000042-26.2017.5.19.0058 | C27: - | D27: Precatório | E27: Alimentar | F27: 20/05/2020 | G27: Autuada | H27: Sim | I27: 0 | J27: Municipal | K27: 2021 | L27: CANAPI | M27: CANAPI | N27: ESPECIAL | O27: Não | P27: VARA DO TRABALHO | Q27: Sim | R27: Vencido | S27: -
A28: 10136/2020 | B28: 0000460-61.2017.5.19.0058 | C28: - | D28: Precatório | E28: Alimentar | F28: 20/05/2020 | G28: Autuada | H28: Sim | I28: 0 | J28: Municipal | K28: 2021 | L28: CANAPI | M28: CANAPI | N28: ESPECIAL | O28: Não | P28: VARA DO TRABALHO | Q28: Sim | R28: Vencido | S28: -
... A35: 10099/2020 | B35: 0000645-02.2017.5.19.0058 | C35: - | D35: Precatório | E35: Alimentar | F35: 15/05/2020 | G35: Autuada | H35: Sim | I35: 0 | J35: Municipal | K35: 2021 | L35: CANAPI | M35: CANAPI | N35: ESPECIAL | O35: Não | P35: VARA DO TRABALHO | Q35: Sim | R35: Vencido | S35: -
A36: 00036/2020 | B36: 0001606-40.2017.5.19.0058 | C36: - | D36: RPV | E36: Alimentar | F36: 15/05/2020 | G36: Autuada | H36: Sim | I36: 31925.21 | J36: Municipal | K36: - | L36: PAO DE ACUCAR | M36: PAO DE ACUCAR | N36: GERAL | O36: Não | P36: VARA DO TRABALHO | Q36: Não | R36: Vencido | S36: 10/08/2020
A37: 10120/2020 | B37: 0000066-54.2017.5.19.0058 | C37: - | D37: Precatório | E37: Alimentar | F37: 18/05/2020 | G37: Autuada | H37: Sim | I37: 0 | J37: Municipal | K37: 2021 | L37: CANAPI | M37: CANAPI | N37: ESPECIAL | O37: Não | P37: VARA DO TRABALHO | Q37: Sim | R37: Vencido | S37: -
A38: 10345/2020 | B38: 0000039-71.2017.5.19.0058 | C38: - | D38: Precatório | E38: Alimentar | F38: 28/05/2020 | G38: Autuada | H38: Sim | I38: 0 | J38: Municipal | K38: 2021 | L38: CANAPI | M38: CANAPI | N38: ESPECIAL | O38: Não | P38: VARA DO TRABALHO | Q38: Sim | R38: Vencido | S38: -
A39: 10123/2020 | B39: 0000943-91.2017.5.19.0058 | C39: - | D39: Precatório | E39: Alimentar | F39: 19/05/2020 | G39: Autuada | H39: Sim | I39: 0 | J39: Municipal | K39: 2021 | L39: CANAPI | M39: CANAPI | N39: ESPECIAL | O39: Não | P39: VARA DO TRABALHO | Q39: Sim | R39: Vencido | S39: -
A40: 10125/2020 | B40: 0000008-14.2018.5.19.0059 | C40: - | D40: Precatório | E40: Alimentar | F40: 19/05/2020 | G40: Autuada | H40: Sim | I40: 0 | J40: Estadual | K40: 2021 | L40: ALAGOAS | M40: ALAGOAS | N40: GERAL | O40: Não | P40: VARA DO TRABALHO | Q40: Sim | R40: Vencido | S40: -
A41: 10159/2020 | B41: 0000727-30.2017.5.19.0059 | C41: - | D41: Precatório | E41: Alimentar | F41: 21/05/2020 | G41: Autuada | H41: Sim | I41: 0 | J41: Municipal | K41: 2021 | L41: PIACABUCU | M41: PIACABUCU | N41: GERAL | O41: Não | P41: VARA DO TRABALHO | Q41: Sim | R41: Vencido | S41: -
A42: 10132/2020 | B42: 0001277-62.2016.5.19.0058 | C42: - | D42: Precatório | E42: Alimentar | F42: 20/05/2020 | G42: Autuada | H42: Sim | I42: 0 | J42: Municipal | K42: 2021 | L42: CANAPI | M42: CANAPI | N42: ESPECIAL | O42: Não | P42: VARA DO TRABALHO | Q42: Sim | R42: Vencido | S42: -
A43: 00040/2020 | B43: 0000093-37.2017.5.19.0058 | C43: - | D43: RPV | E43: Alimentar | F43: 20/05/2020 | G43: Autuada | H43: Sim | I43: 6101.06 | J43: Municipal | K43: - | L43: CANAPI | M43: CANAPI | N43: ESPECIAL | O43: Não | P43: VARA DO TRABALHO | Q43: Não | R43: Vencido | S43: 20/09/2019
A44: 10164/2020 | B44: 0001352-35.2015.5.19.0059 | C44: - | D44: Precatório | E44: Alimentar | F44: 21/05/2020 | G44: Autuada | H44: Sim | I44: 0 | J44: Estadual | K44: 2021 | L44: ALAGOAS | M44: ALAGOAS | N44: GERAL | O44: Não | P44: VARA DO TRABALHO | Q44: Sim | R44: Vencido | S44: -
A45: 10313/2020 | B45: 0000922-18.2017.5.19.0058 | C45: - | D45: Precatório | E45: Alimentar | F45: 27/05/2020 | G45: Autuada | H45: Sim | I45: 0 | J45: Municipal | K45: 2021 | L45: CANAPI | M45: CANAPI | N45: ESPECIAL | O45: Não | P45: VARA DO TRABALHO | Q45: Sim | R45: Vencido | S45: -
A46: 10166/2020 | B46: 0190200-91.2003.5.19.0005 | C46: - | D46: Precatório | E46: Alimentar | F46: 21/05/2020 | G46: Cancelada | H46: Sim | I46: 22797.83 | J46: Estadual | K46: 2021 | L46: ALAGOAS | M46: UNIVERSIDADE ESTADUAL DE CIENCIAS DA SAUDE DE ALAGOAS - UNCISAL | N46: GERAL | O46: Não | P46: 5ª VARA DO TRABALHO | Q46: Sim | R46: Vencido | S46: -
...

Sheet Relatório
A1: Nº da RP | B1: Nº do Processo | C1: Precatório/RPV | D1: Tipo de Requisição | E1: Natureza do Crédito | F1: Data da Autuação | G1: Situação da RP | H1: RP Publicada | I1: Valor Atual | J1: Esfera | K1: Ente Devedor | L1: Entidade Devedora (Executado) | M1: Regime Pagamento | N1: Permite acordo Direto | O1: Vara de Origem | P1: Possui Convênio | Q1: Prazo de Pagamento | R1: Data Fim Prazo de Pagamento
A2: 00001/2020 | B2: 0000702-82.2017.5.19.0005 | C2: - | D2: RPV | E2: Alimentar | F2: 02/04/2020 | G2: Autuada | H2: Não | I2: 16746.27 | J2: Municipal | K2: RIO LARGO | L2: RIO LARGO | M2: GERAL | N2: Não | O2: 5ª VARA DO TRABALHO | P2: Não | Q2: No Prazo | R2: -
A3: 00008/2020 | B3: 0000044-52.2017.5.19.0007 | C3: - | D3: RPV | E3: Comum | F3: 26/04/2020 | G3: Autuada | H3: Não | I3: 28807.62 | J3: Municipal | K3: RIO LARGO | L3: RIO LARGO | M3: GERAL | N3: Não | O3: 7ª VARA DO TRABALHO | P3: Não | Q3: No Prazo | R3: -
A4: 00305/2020 | B4: 0000251-12.2019.5.19.0062 | C4: - | D4: RPV | E4: Alimentar | F4: 12/08/2020 | G4: Autuada | H4: Não | I4: 20089.08 | J4: Municipal | K4: ROTEIRO | L4: ROTEIRO | M4: GERAL | N4: Não | O4: 1ª VARA DO TRABALHO | P4: Não | Q4: No Prazo | R4: -
A5: 00507/2020 | B5: 0001036-07.2017.5.19.0009 | C5: - | D5: RPV | E5: Alimentar | F5: 05/11/2020 | G5: Autuada | H5: Não | I5: 5153.46 | J5: Municipal | K5: RIO LARGO | L5: RIO LARGO | M5: GERAL | N5: Não | O5: 1ª VARA DO TRABALHO | P5: Não | Q5: Vencido | R5: 25/01/2021
A6: 00521/2020 | B6: 0000510-21.2018.5.19.0004 | C6: - | D6: RPV | E6: Alimentar | F6: 12/11/2020 | G6: Autuada | H6: Não | I6: 0 | J6: Municipal | K6: RIO LARGO | L6: RIO LARGO | M6: GERAL | N6: Não | O6: 1ª VARA DO TRABALHO | P6: Não | Q6: Vencido | R6: 10/03/2022
A7: 00583/2020 | B7: 0000265-08.2019.5.19.0058 | C7: - | D7: RPV | E7: Alimentar | F7: 01/12/2020 | G7: Autuada | H7: Não | I7: 9222.76 | J7: Municipal | K7: AGUA BRANCA | L7: AGUA BRANCA | M7: GERAL | N7: Não | O7: VARA DO TRABALHO | P7: Não | Q7: No Prazo | R7: -
A8: 00610/2020 | B8: 0000225-66.2018.5.19.0056 | C8: - | D8: RPV | E8: Alimentar | F8: 03/12/2020 | G8: Autuada | H8: Não | I8: 0 | J8: Municipal | K8: PASSO DE CAMARAGIBE | L8: PASSO DE CAMARAGIBE | M8: GERAL | N8: Não | O8: VARA DO TRABALHO | P8: Não | Q8: No Prazo | R8: -
A9: 00643/2020 | B9: 0001938-07.2017.5.19.0058 | C9: - | D9: RPV | E9: Alimentar | F9: 17/12/2020 | G9: Autuada | H9: Não | I9: 8145.28 | J9: Municipal | K9: PAO DE ACUCAR | L9: PAO DE ACUCAR | M9: GERAL | N9: Não | O9: VARA DO TRABALHO | P9: Não | Q9: Vencido | R9: 31/03/2021
A10: 01404/2021 | B10: 0000777-79.2019.5.19.0061 | C10: - | D10: RPV | E10: Alimentar | F10: 11/08/2021 | G10: Autuada | H10: Não | I10: 14681.71 | J10: Estadual | K10: ALAGOAS | L10: ESTADO DE ALAGOAS | M10: GERAL | N10: Não | O10: 2ª VARA DO TRABALHO | P10: Não | Q10: No Prazo | R10: -
A11: 01372/2023 | B11: 0000235-39.2022.5.19.0002 | C11: - | D11: RPV | E11: Alimentar | F11: 04/08/2023 | G11: Autuada | H11: Não | I11: 4241.88 | J11: Federal | K11: UNIÃO FEDERAL (AGU) | L11: EMPRESA BRASILEIRA DE SERVICOS HOSPITALARES - EBSERH | M11: GERAL | N11: Não | O11: 3ª VARA DO TRABALHO | P11: Não | Q11: No Prazo | R11: -
A12: 02534/2024 | B12: 0060300-21.1990.5.19.0002 | C12: 0002621-77.2024.5.19.0000 | D12: RPV | E12: Alimentar | F12: 08/05/2024 | G12: Autuada | H12: Não | I12: 8189.74 | J12: Federal | K12: UNIÃO FEDERAL (AGU) | L12: INSTITUTO NACIONAL DE SEGURIDADE SOCIAL | M12: GERAL | N12: Não | O12: 2ª VARA DO TRABALHO | P12: Não | Q12: No Prazo | R12: -
A13: 02536/2024 | B13: 0060300-21.1990.5.19.0002 | C13: 0002622-62.2024.5.19.0000 | D13: RPV | E13: Alimentar | F13: 08/05/2024 | G13: Autuada | H13: Não | I13: 69441.85 | J13: Federal | K13: UNIÃO FEDERAL (AGU) | L13: INSTITUTO NACIONAL DE SEGURIDADE SOCIAL | M13: GERAL | N13: Não | O13: 2ª VARA DO TRABALHO | P13: Não | Q13: No Prazo | R13: -
... A420: 00194/2026 | B420: 0000291-19.2020.5.19.0010 | C420: 0000241-13.2026.5.19.0000 | D420: Precatório | E420: Alimentar | F420: 30/01/2026 | G420: Autuada | H420: Não | I420: 14736.5 | J420: Estadual | K420: SERVICOS DE ENGENHARIA DO ESTADO DE ALAGOAS S/A SERVEAL | L420: SERVICOS DE ENGENHARIA DO ESTADO DE ALAGOAS S/A SERVEAL | M420: GERAL | N420: Não | O420: 10ª VARA DO TRABALHO | P420: Sim | Q420: No Prazo | R420: -
A421: 00248/2026 | B421: 0001123-13.2024.5.19.0010 | C421: 0000288-84.2026.5.19.0000 | D421: Precatório | E421: Alimentar | F421: 46073 | G421: Autuada | H421: Não | I421: 52600.14 | J421: Estadual | K421: ALAGOAS | L421: ALAGOAS | M421: GERAL | N421: Não | O421: 6ª VARA DO TRABALHO | P421: Sim | Q421: No Prazo | S421: -
A422: 00246/2026 | B422: 0000500-24.2025.5.19.0006 | C422: 0000286-17.2026.5.19.0000 | D422: Precatório | E422: Alimentar | F422: 46073 | G422: Autuada | H422: Não | I422: 45523.95 | J422: Estadual | K422: ALAGOAS | L422: ALAGOAS | M422: GERAL | N422: Não | O422: 6ª VARA DO TRABALHO | P422: Sim | Q422: No Prazo | S422: -
A423: 00253/2026 | B423: 0000155-38.2021.5.19.0058 | C423: 0000294-91.2026.5.19.0000 | D423: Precatório | E423: Alimentar | F423: 46073 | G423: Autuada | H423: Não | I423: 21784.83 | J423: Municipal | K423: PARICONHA | L423: PARICONHA | M423: GERAL | N423: Não | O423: VARA DO TRABALHO | P423: Sim | Q423: No Prazo
A424: 00250/2026 | B424: 0001272-21.2024.5.19.0006 | C424: 0000291-39.2026.5.19.0000 | D424: Precatório | E424: Alimentar | F424: 46073 | G424: Autuada | H424: Não | I424: 44790.33 | J424: Estadual | K424: ALAGOAS | L424: ALAGOAS | M424: GERAL | N424: Não | O424: 6ª VARA DO TRABALHO | P424: Sim | Q424: No Prazo | R424: -
A425: 00252/2026 | B425: 0000628-84.2024.5.19.0004 | C425: 0000293-09.2026.5.19.0000 | D425: Precatório | E425: Alimentar | F425: 46073 | G425: Autuada | H425: Não | I425: 109955.99 | J425: Estadual | K425: ALAGOAS | L425: ALAGOAS | M425: GERAL | N425: Não | O425: 4ª VARA DO TRABALHO | P425: Sim | Q425: No Prazo | R425: -
A426: 00254/2026 | B426: 0001273-06.2024.5.19.0006 | C426: 0000304-38.2026.5.19.0000 | D426: Precatório | E426: Alimentar | F426: 46073 | G426: Autuada | H426: Não | I426: 46186.71 | J426: Estadual | K426: ALAGOAS | L426: ALAGOAS | M426: GERAL | N426: Não | O426: 6ª VARA DO TRABALHO | P426: Sim | Q426: No Prazo | R426: -
A427: 00258/2026 | B427: 0001427-24.2024.5.19.0006 | C427: 0000307-90.2026.5.19.0000 | D427: Precatório | E427: Alimentar | F427: 46073 | G427: Autuada | H427: Não | I427: 42317.35 | J427: Estadual | K427: ALAGOAS | L427: ALAGOAS | M427: GERAL | N427: Não | O427: 6ª VARA DO TRABALHO | P427: Sim | Q427: No Prazo | R427: -
A428: 00255/2026 | B428: 0001299-04.2024.5.19.0006 | C428: 0000303-53.2026.5.19.0000 | D428: Precatório | E428: Alimentar | F428: 46073 | G428: Autuada | H428: Não | I428: 39982.32 | J428: Estadual | K428: ALAGOAS | L428: ALAGOAS | M428: GERAL | N428: Não | O428: 6ª VARA DO TRABALHO | P428: Sim | Q428: No Prazo | R428: -
A429: 00256/2026 | B429: 0001395-19.2024.5.19.0006 | C429: 0000305-23.2026.5.19.0000 | D429: Precatório | E429: Alimentar | F429: 46073 | G429: Autuada | H429: Não | I429: 76030.14 | J429: Estadual | K429: ALAGOAS | L429: ALAGOAS | M429: GERAL | N429: Não | O429: 6ª VARA DO TRABALHO | P429: Sim | Q429: No Prazo | R429: -
A430: 00257/2026 | B430: 0000272-83.2024.5.19.0006 | C430: 0000306-08.2026.5.19.0000 | D430: Precatório | E430: Alimentar | F430: 46073 | G430: Autuada | H430: Não | I430: 41817.14 | J430: Estadual | K430: ALAGOAS | L430: ALAGOAS | M430: GERAL | N430: Não | O430: 6ª VARA DO TRABALHO | P430: Sim | Q430: No Prazo | R430: -
A431: 00249/2026 | B431: 0001204-71.2024.5.19.0006 | C431: 0000289-69.2026.5.19.0000 | D431: Precatório | E431: Alimentar | F431: 46073 | G431: Autuada | H431: Não | I431: 42200.53 | J431: Estadual | K431: ALAGOAS | L431: ALAGOAS | M431: GERAL | N431: Não | O431: 6ª VARA DO TRABALHO | P431: Sim | Q431: No Prazo | R431: -
A432: 00251/2026 | B432: 0001293-94.2024.5.19.0006 | C432: 0000292-24.2026.5.19.0000 | D432: Precatório | E432: Alimentar | F432: 46073 | G432: Autuada | H432: Não | I432: 46397.05 | J432: Estadual | K432: ALAGOAS | L432: ALAGOAS | M432: GERAL | N432: Não | O432: 6ª VARA DO TRABALHO | P432: Sim | Q432: No Prazo
A433: 00247/2026 | B433: 0000840-02.2024.5.19.0006 | C433: 0000287-02.2026.5.19.0000 | D433: Precatório | E433: Alimentar | F433: 46073 | G433: Autuada | H433: Não | I433: 60697.89 | J433: Estadual | K433: ALAGOAS | L433: COMPANHIA ALAGOANA DE RECURSOS HUMANOS E PATRIMONIAIS | M433: GERAL | N433: Não | O433: 6ª VARA DO TRABALHO | P433: Sim | Q433: No Prazo | R433: -

Sheet Dinamica - Em Validação
A1: TIPO | B1: Precatório
A3: Rótulos de Linha | B3: PROCESSO
A4: ALAGOAS | B4: 0000191-14.2022.5.19.0004
B5: 0000457-98.2022.5.19.0004
B6: 0000645-17.2024.5.19.0006
B7: 0000732-76.2024.5.19.0004
B8: 0001244-59.2024.5.19.0004
B9: 0001412-61.2024.5.19.0004
B10: 0141700-66.2004.5.19.0002
A11: BARRA DE SANTO ANTONIO | B11: 0000567-43.2019.5.19.0056
A12: CONSÓRCIO DE SANEAMENTO BÁSICO DO BAIXO SÃO FRANCISCO SERGIPANO | B12: 0000707-63.2022.5.19.0059
A13: EMPRESA BRASILEIRA DE SERVICOS HOSPITALARES-EBSERH | B13: 0000166-85.2019.5.19.0010
A14: PAULO JACINTO | B14: 0000238-39.2021.5.19.0063
A15: PORTO DE PEDRAS | B15: 0001815-80.2015.5.19.0057
A16: SATUBA | B16: 0000320-25.2013.5.19.0007
A17: SERVICO AUTONOMO DE AGUA E ESGOTO | B17: 0000196-65.2022.5.19.0059
A18: Total Geral

Sheet Em Validação
A1: ID | B1: PROCESSO | C1: PRECATORIO | D1: VARA | E1: BENEFICIARIOS | F1: ENTE | G1: TIPO | H1: DATA
A2: 14738 | B2: 0000707-63.2022.5.19.0059 | D2: VARA DO TRABALHO DE PENEDO | E2: JAIRO GOMES DOS SANTOS | F2: CONSÓRCIO DE SANEAMENTO BÁSICO DO BAIXO SÃO FRANCISCO SERGIPANO | G2: Precatório | H2: 45544
A3: 15255 | B3: 0000196-65.2022.5.19.0059 | D3: VARA DO TRABALHO DE PENEDO | E3: OTAVIANO JOSE GUIMARAES NOBRE | F3: SERVICO AUTONOMO DE AGUA E ESGOTO | G3: Precatório | H3: 45671
A4: 15625 | B4: 0000320-25.2013.5.19.0007 | D4: 7ª VARA DO TRABALHO DE MACEIÓ | E4: UNIÃO FEDERAL (PGFN) | F4: SATUBA | G4: Precatório | H4: 45740
A5: 16142 | B5: 0000309-79.2025.5.19.0005 | D5: 5ª VARA DO TRABALHO DE MACEIÓ | E5: SINDICATO DOS TRAB. EM SEGURIDADE SOCIAL, SAUDE, PREV., SEGURO SOCIAL, ASSIST. SOCIAL E TRAB. NO EST. DE ALAGOAS-SINDPREV-AL | F5: UNIÃO FEDERAL (AGU) | G5: RPV | H5: 45849
A6: 16129 | B6: 0000425-85.2025.5.19.0005 | D6: 5ª VARA DO TRABALHO DE MACEIÓ | E6: SINDICATO DOS TRAB. EM SEGURIDADE SOCIAL, SAUDE, PREV., SEGURO SOCIAL, ASSIST. SOCIAL E TRAB. NO EST. DE ALAGOAS-SINDPREV-AL | F6: UNIÃO FEDERAL (AGU) | G6: RPV | H6: 45848
A7: 16101 | B7: 0000313-19.2025.5.19.0005 | D7: 5ª VARA DO TRABALHO DE MACEIÓ | E7: SINDICATO DOS TRAB. EM SEGURIDADE SOCIAL, SAUDE, PREV., SEGURO SOCIAL, ASSIST. SOCIAL E TRAB. NO EST. DE ALAGOAS-SINDPREV-AL | F7: UNIÃO FEDERAL (AGU) | G7: RPV | H7: 45847
A8: 16097 | B8: 0000416-26.2025.5.19.0005 | D8: 5ª VARA DO TRABALHO DE MACEIÓ | E8: SINDICATO DOS TRAB. EM SEGURIDADE SOCIAL, SAUDE, PREV., SEGURO SOCIAL, ASSIST. SOCIAL E TRAB. NO EST. DE ALAGOAS-SINDPREV-AL | F8: UNIÃO FEDERAL (AGU) | G8: RPV | H8: 45846
A9: 16069 | B9: 0000332-25.2025.5.19.0005 | D9: 5ª VARA DO TRABALHO DE MACEIÓ | E9: SINDICATO DOS TRAB. EM SEGURIDADE SOCIAL, SAUDE, PREV., SEGURO SOCIAL, ASSIST. SOCIAL E TRAB. NO EST. DE ALAGOAS-SINDPREV-AL | F9: UNIÃO FEDERAL (AGU) | G9: RPV | H9: 45843
A10: 15919 | B10: 0000312-34.2025.5.19.0005 | D10: 5ª VARA DO TRABALHO DE MACEIÓ | E10: SINDICATO DOS TRAB. EM SEGURIDADE SOCIAL, SAUDE, PREV., SEGURO SOCIAL, ASSIST. SOCIAL E TRAB. NO EST. DE ALAGOAS-SINDPREV-AL | F10: UNIÃO FEDERAL (AGU) | G10: RPV | H10: 45814
A11: 16474 | B11: 0000314-04.2025.5.19.0005 | D11: 5ª VARA DO TRABALHO DE MACEIÓ | E11: SINDICATO DOS TRAB. EM SEGURIDADE SOCIAL, SAUDE, PREV., SEGURO SOCIAL, ASSIST. SOCIAL E TRAB. NO EST. DE ALAGOAS-SINDPREV-AL | F11: UNIÃO FEDERAL (AGU) | G11: RPV | H11: 45902
A12: 16503 | B12: 0000511-75.2024.5.19.0010 | D12: 10ª VARA DO TRABALHO DE MACEIÓ | E12: ALINE NASCIMENTO BAPTISTA DE OLIVEIRA | F12: UNIÃO FEDERAL (AGU) | G12: RPV | H12: 45911
A13: 16562 | B13: 0000125-58.2018.5.19.0009 | D13: 9ª VARA DO TRABALHO DE MACEIÓ | E13: RAFAEL RAMOS PEDROSA | F13: UNIÃO FEDERAL (AGU) | G13: RPV | H13: 45917
... A54: 16920 | B54: 0000614-23.2010.5.19.0059 | D54: VARA DO TRABALHO DE PENEDO | E54: MANOEL EVANGELISTA SILVA | F54: UNIÃO FEDERAL (AGU) | G54: RPV | H54: 45996
A55: 16643 | B55: 0001815-80.2015.5.19.0057 | C55: 0000066-19.2026.5.19.0000 | D55: VARA DO TRABALHO DE PORTO CALVO | E55: ADERSON FRANCA DA SILVA | F55: PORTO DE PEDRAS | G55: Precatório | H55: 45937
A56: 17090 | B56: 0001244-59.2024.5.19.0004 | D56: 4ª VARA DO TRABALHO DE MACEIÓ | E56: MARIA CRISTINA DAVINO LOBO | F56: ALAGOAS | G56: Precatório | H56: 46043
A57: 17090 | B57: 0001244-59.2024.5.19.0004 | D57: 4ª VARA DO TRABALHO DE MACEIÓ | E57: ANDRE VILACA DOS SANTOS | F57: ALAGOAS | G57: Precatório | H57: 46043
A58: 17091 | B58: 0001244-59.2024.5.19.0004 | D58: 4ª VARA DO TRABALHO DE MACEIÓ | E58: UNIÃO FEDERAL (PGF) | F58: ALAGOAS | G58: Precatório | H58: 46043
A59: 17046 | B59: 0000294-10.2025.5.19.0006 | D59: 11ª VARA DO TRABALHO DE MACEIÓ | E59: FATIMA MARIA PENHA REIS | F59: UNIÃO FEDERAL (AGU) | G59: Precatório | H59: 46038
A60: 17046 | B60: 0000294-10.2025.5.19.0006 | D60: 11ª VARA DO TRABALHO DE MACEIÓ | E60: JOSE OLIVEIRA COSTA | F60: UNIÃO FEDERAL (AGU) | G60: Precatório | H60: 46038
A61: 17069 | B61: 0000457-98.2022.5.19.0004 | D61: 4ª VARA DO TRABALHO DE MACEIÓ | E61: EDMILSON MATIAS GONCALVES | F61: ALAGOAS | G61: Precatório | H61: 46038
A62: 16994 | B62: 0000645-17.2024.5.19.0006 | D62: 6ª VARA DO TRABALHO DE MACEIÓ | E62: Michel Bomfim Sociedade Individual | F62: ALAGOAS | G62: Precatório | H62: 46030
A63: 16994 | B63: 0000645-17.2024.5.19.0006 | D63: 6ª VARA DO TRABALHO DE MACEIÓ | E63: LOURINALDO CORREIA CORDEIRO | F63: ALAGOAS | G63: Precatório | H63: 46030
A64: 17171 | B64: 0000072-86.2025.5.19.0056 | D64: VARA DO TRABALHO DE SÃO LUÍS DO QUITUNDE | E64: CENTRAL ACUCAREIRA SANTO ANTONIO S A | F64: UNIÃO FEDERAL (AGU) | G64: RPV | H64: 46064
A65: 17159 | B65: 0000567-43.2019.5.19.0056 | D65: VARA DO TRABALHO DE SÃO LUÍS DO QUITUNDE | E65: SINDICATO DOS SERVIDORES PUBLICOS DO MUNICIPIO DE MACEIO E REGIAO METROPOLITANA DO ESTADO DE ALAGOAS | F65: BARRA DE SANTO ANTONIO | G65: Precatório | H65: 46059
A66: 17174 | B66: 0000789-88.2024.5.19.0006 | D66: 3ª VARA DO TRABALHO DE MACEIÓ | E66: ROSELE DE SOUZA MELO | F66: UNIÃO FEDERAL (AGU) | G66: Precatório | H66: 46065
A67: 17063 | B67: 0000305-45.2025.5.19.0004 | D67: 11ª VARA DO TRABALHO DE MACEIÓ | E67: MARIA DO SOCORRO MARTINS MACHADO BARROS | F67: UNIÃO FEDERAL (AGU) | G67: Precatório | H67: 46038
... A91: 17111 | B91: 0000191-14.2022.5.19.0004 | D91: 4ª VARA DO TRABALHO DE MACEIÓ | E91: UNIÃO FEDERAL (PGF) | F91: ALAGOAS | G91: Precatório | H91: 46048

Sheet Dinamica - Em Dilig. F
A2: TIPO DEVEDOR | B2: FEDERAL
A4: Rótulos de Linha
A5: Precatório
A6: 0000001-49.2025.5.19.0003
A7: 0000003-04.2025.5.19.0008
A8: 0000004-07.2025.5.19.0002
A9: 0000005-65.2025.5.19.0010
A10: 0000005-89.2025.5.19.0002
A11: 0000005-92.2025.5.19.0001
A12: 0000166-85.2019.5.19.0010
A13: 0000253-94.2021.5.19.0002
A14: 0000272-49.2025.5.19.0006
A15: 0000273-34.2025.5.19.0006
... A130: Total Geral

Sheet Dinamica - Em Dilig. 
A1: TIPO DEVEDOR | B1: (Vários itens)
A2: TIPO DE REQUISIÇÃO | B2: Precatório
A4: Rótulos de Linha
A5: ALAGOAS
A6: 0000150-04.2023.5.19.0007
A7: 0000151-38.2022.5.19.0002
A8: 0000179-06.2022.5.19.0002
A9: 0000210-26.2022.5.19.0002
A10: 0000306-09.2020.5.19.0003
A11: 0000308-70.2011.5.19.0010
A12: 0000349-92.2024.5.19.0006
A13: 0000358-37.2022.5.19.0002
A14: 0000389-26.2012.5.19.0061
A15: 0000438-29.2021.5.19.0004
... A72: Total Geral

Sheet Em diligência
A2: ID | B2: Nº PROCESSO | C2: Nº PRECATÓRIO/RPV | D2: VARA DE ORIGEM | E2: BENEFICIÁRIOS | F2: DEVEDOR | G2: TIPO DEVEDOR | H2: TIPO DE REQUISIÇÃO | I2: NATUREZA | J2: DATA DE CRIAÇÃO
A3: 16969 | B3: 0000009-98.2020.5.19.0262 | C3: 0000137-21.2026.5.19.0000 | D3: 2ª VARA DO TRABALHO DE SÃO MIGUEL DOS CAMPOS | E3: MARIA LUCIENE GOMES DA SILVA | F3: SAO MIGUEL DOS CAMPOS | G3: MUNICIPIOS | H3: Precatório | I3: Alimentar | J3: 46010
A4: 16931 | B4: 0000516-86.2025.5.19.0261 | D4: 2ª VARA DO TRABALHO DE ARAPIRACA | E4: UNIVERSO VERDE COMERCIO DE ALIMENTOS LTDA | F4: UNIÃO FEDERAL (AGU) | G4: FEDERAL | H4: RPV | I4: Alimentar | J4: 46000
A5: 16752 | B5: 0001231-23.2016.5.19.0010 | C5: 0000110-38.2026.5.19.0000 | D5: 10ª VARA DO TRABALHO DE MACEIÓ | E5: CONFEDERACAO DOS SERVIDORES PUBLICOS DO BRASIL C S P B | F5: ALAGOAS | G5: ESTADUAL | H5: Precatório | I5: Alimentar | J5: 45971
A6: 16737 | B6: 0000234-89.2018.5.19.0262 | C6: 0000093-02.2026.5.19.0000 | D6: 2ª VARA DO TRABALHO DE SÃO MIGUEL DOS CAMPOS | E6: JOSINETE ANDRADE DA SILVA | F6: BARRA DE SAO MIGUEL | G6: MUNICIPIOS | H6: Precatório | I6: Alimentar | J6: 45966
A7: 16655 | B7: 0001129-20.2019.5.19.0002 | C7: 0000114-75.2026.5.19.0000 | D7: 2ª VARA DO TRABALHO DE MACEIÓ | E7: MARIA GORETE GOMES | F7: RIO LARGO | G7: MUNICIPIOS | H7: Precatório | I7: Alimentar | J7: 45940
A8: 16576 | B8: 0000536-78.2023.5.19.0057 | C8: 0000049-80.2026.5.19.0000 | D8: VARA DO TRABALHO DE PORTO CALVO | E8: PAULINE SILVA DOS SANTOS | F8: ALAGOAS | G8: ESTADUAL | H8: Precatório | I8: Alimentar | J8: 45923
A9: 16550 | B9: 0151600-42.2005.5.19.0001 | C9: 0000046-28.2026.5.19.0000 | D9: 1ª VARA DO TRABALHO DE MACEIÓ | E9: ANDRE VILACA DOS SANTOS | F9: ALAGOAS | G9: ESTADUAL | H9: Precatório | I9: Alimentar | J9: 45915
A10: 16550 | B10: 0151600-42.2005.5.19.0001 | C10: 0000046-28.2026.5.19.0000 | D10: 1ª VARA DO TRABALHO DE MACEIÓ | E10: ANTONIO ELIAS DA SILVA | F10: ALAGOAS | G10: ESTADUAL | H10: Precatório | I10: Alimentar | J10: 45915
A11: 16546 | B11: 0001254-34.2023.5.19.0006 | D11: 1ª VARA DO TRABALHO DE MACEIÓ | E11: MARIA CLEIDE MELO COSTA | F11: MACEIO | G11: MUNICIPIOS | H11: Precatório | I11: Alimentar | J11: 45915
A12: 16545 | B12: 0000306-09.2020.5.19.0003 | C12: 0000041-06.2026.5.19.0000 | D12: 1ª VARA DO TRABALHO DE MACEIÓ | E12: LUCIANO ANDRE COSTA DE ALMEIDA | F12: ALAGOAS | G12: ESTADUAL | H12: Precatório | I12: Alimentar | J12: 45915
A13: 16544 | B13: 0000306-09.2020.5.19.0003 | C13: 0000042-88.2026.5.19.0000 | D13: 1ª VARA DO TRABALHO DE MACEIÓ | E13: ROSANUBIA VASCONCELOS DE BARROS LIMA | F13: ALAGOAS | G13: ESTADUAL | H13: Precatório | I13: Alimentar | J13: 45915
A14: 16540 | B14: 0139400-25.1990.5.19.0002 | D14: 2ª VARA DO TRABALHO DE MACEIÓ | E14: SERGIO MATIAS DE MENDONCA | F14: UNIÃO FEDERAL (AGU) | G14: FEDERAL | H14: Precatório | I14: Alimentar | J14: 45915
A15: 16537 | B15: 0139400-25.1990.5.19.0002 | D15: 2ª VARA DO TRABALHO DE MACEIÓ | E15: LUIZ DE FRANCA PORFIRIO | F15: UNIÃO FEDERAL (AGU) | G15: FEDERAL | H15: Precatório | I15: Alimentar | J15: 45915
A16: 16534 | B16: 0139400-25.1990.5.19.0002 | D16: 2ª VARA DO TRABALHO DE MACEIÓ | E16: JOSE DE LIMA FILHO | F16: UNIÃO FEDERAL (AGU) | G16: FEDERAL | H16: Precatório | I16: Alimentar | J16: 45915
A17: 16532 | B17: 0139400-25.1990.5.19.0002 | D17: 2ª VARA DO TRABALHO DE MACEIÓ | E17: FRANCISCO ANTONIO DE SOUZA | F17: UNIÃO FEDERAL (AGU) | G17: FEDERAL | H17: Precatório | I17: Alimentar | J17: 45915
A18: 16531 | B18: 0139400-25.1990.5.19.0002 | D18: 2ª VARA DO TRABALHO DE MACEIÓ | E18: EDUARDO JOSE COSTA NEVES | F18: UNIÃO FEDERAL (AGU) | G18: FEDERAL | H18: Precatório | I18: Alimentar | J18: 45915
A19: 16530 | B19: 0139400-25.1990.5.19.0002 | D19: 2ª VARA DO TRABALHO DE MACEIÓ | E19: CLEBER VORONKOFF CARNAUBA | F19: UNIÃO FEDERAL (AGU) | G19: FEDERAL | H19: Precatório | I19: Alimentar | J19: 45915
A20: 16529 | B20: 0139400-25.1990.5.19.0002 | D20: 2ª VARA DO TRABALHO DE MACEIÓ | E20: CARLOS SILVA GOIS | F20: UNIÃO FEDERAL (AGU) | G20: FEDERAL | H20: Precatório | I20: Alimentar | J20: 45915
A21: 16500 | B21: 0000421-39.2023.5.19.0063 | C21: 0000059-27.2026.5.19.0000 | D21: VARA DO TRABALHO DE PALMEIRA DOS ÍNDIOS | E21: AILTON GRACINDO SILVA DAS NEVES | F21: PALMEIRA DOS INDIOS | G21: MUNICIPIOS | H21: Precatório | I21: Alimentar | J21: 45911
A22: 16486 | B22: 0000146-22.2025.5.19.0063 | C22: 0000031-59.2026.5.19.0000 | D22: VARA DO TRABALHO DE PALMEIRA DOS ÍNDIOS | E22: ERICA DE OLIVEIRA SANTOS FERREIRA | F22: PALMEIRA DOS INDIOS | G22: MUNICIPIOS | H22: Precatório | I22: Alimentar | J22: 45904
A23: 16475 | B23: 0001297-83.2012.5.19.0061 | D23: 2ª VARA DO TRABALHO DE ARAPIRACA | E23: JOSE LUIS DOS SANTOS | F23: UNIÃO FEDERAL (AGU) | G23: FEDERAL | H23: RPV | I23: Alimentar | J23: 45902
A24: 16381 | B24: 0000304-07.2021.5.19.0261 | D24: 2ª VARA DO TRABALHO DE ARAPIRACA | E24: MINISTÉRIO PÚBLICO DO TRABALHO | F24: CAMPO ALEGRE | G24: MUNICIPIOS | H24: Precatório | I24: Alimentar | J24: 45881
A25: 16379 | B25: 0000554-87.2023.5.19.0061 | D25: 2ª VARA DO TRABALHO DE ARAPIRACA | E25: JULIA CAROLLINE SILVA LIRA | F25: UNIÃO FEDERAL (AGU) | G25: FEDERAL | H25: RPV | I25: Alimentar | J25: 45881
A26: 16323 | B26: 0000312-40.2025.5.19.0003 | D26: 2ª VARA DO TRABALHO DE MACEIÓ | E26: MARGARIDA GONCALVES PEREIRA DE GOIS | F26: UNIÃO FEDERAL (AGU) | G26: FEDERAL | H26: Precatório | I26: Alimentar | J26: 45868
A27: 16323 | B27: 0000312-40.2025.5.19.0003 | D27: 2ª VARA DO TRABALHO DE MACEIÓ | E27: JOSE OLIVEIRA COSTA | F27: UNIÃO FEDERAL (AGU) | G27: FEDERAL | H27: Precatório | I27: Alimentar | J27: 45868
A28: 16322 | B28: 0000311-58.2025.5.19.0002 | D28: 2ª VARA DO TRABALHO DE MACEIÓ | E28: MARIA DO CARMO TORRES SANTOS | F28: UNIÃO FEDERAL (AGU) | G28: FEDERAL | H28: Precatório | I28: Alimentar | J28: 45868
A29: 16322 | B29: 0000311-58.2025.5.19.0002 | D29: 2ª VARA DO TRABALHO DE MACEIÓ | E29: JOSE OLIVEIRA COSTA | F29: UNIÃO FEDERAL (AGU) | G29: FEDERAL | H29: Precatório | I29: Alimentar | J29: 45868
A30: 16312 | B30: 0000873-46.2025.5.19.0009 | D30: 2ª VARA DO TRABALHO DE MACEIÓ | E30: JOSE OLIVEIRA COSTA | F30: UNIÃO FEDERAL (AGU) | G30: FEDERAL | H30: Precatório | I30: Alimentar | J30: 45868
A31: 16312 | B31: 0000873-46.2025.5.19.0009 | D31: 2ª VARA DO TRABALHO DE MACEIÓ | E31: ALCIONE ROCHA SOUTO | F31: UNIÃO FEDERAL (AGU) | G31: FEDERAL | H31: Precatório | I31: Alimentar | J31: 45868
A32: 16311 | B32: 0000314-86.2025.5.19.0010 | D32: 2ª VARA DO TRABALHO DE MACEIÓ | E32: VERA LUCIA ELIAS RODRIGUES | F32: UNIÃO FEDERAL (AGU) | G32: FEDERAL | H32: Precatório | I32: Alimentar | J32: 45868
A33: 16311 | B33: 0000314-86.2025.5.19.0010 | D33: 2ª VARA DO TRABALHO DE MACEIÓ | E33: JOSE OLIVEIRA COSTA | F33: UNIÃO FEDERAL (AGU) | G33: FEDERAL | H33: Precatório | I33: Alimentar | J33: 45868
A34: 16305 | B34: 0000313-04.2025.5.19.0010 | D34: 2ª VARA DO TRABALHO DE MACEIÓ | E34: PEDRO GOMES FILHO | F34: UNIÃO FEDERAL (AGU) | G34: FEDERAL | H34: Precatório | I34: Alimentar | J34: 45867
... A37: 16289 | B37: 0000306-33.2025.5.19.0003 | D37: 2ª VARA DO TRABALHO DE MACEIÓ | E37: JOSE OLIVEIRA COSTA | F37: UNIÃO FEDERAL (AGU) | G37: FEDERAL | H37: Precatório | I37: Alimentar | J37: 45866
A38: 16286 | B38: 0000056-71.2021.5.19.0057 | C38: 0000010-83.2026.5.19.0000 | D38: VARA DO TRABALHO DE PORTO CALVO | E38: PRISCILLA DE MELO LAMENHA LINS | F38: PORTO CALVO | G38: MUNICIPIOS | H38: Precatório | I38: Alimentar | J38: 45863
A39: 16286 | B39: 0000056-71.2021.5.19.0057 | C39: 0000010-83.2026.5.19.0000 | D39: VARA DO TRABALHO DE PORTO CALVO | E39: BRENDA BRAGA FURTADO | F39: PORTO CALVO | G39: MUNICIPIOS | H39: Precatório | I39: Alimentar | J39: 45863
A40: 16282 | B40: 0000307-06.2025.5.19.0007 | D40: 11ª VARA DO TRABALHO DE MACEIÓ | E40: MARIA DE FATIMA GONCALVES ROCHA | F40: UNIÃO FEDERAL (AGU) | G40: FEDERAL | H40: Precatório | I40: Alimentar | J40: 45862
A41: 16282 | B41: 0000307-06.2025.5.19.0007 | D41: 11ª VARA DO TRABALHO DE MACEIÓ | E41: JOSE OLIVEIRA COSTA | F41: UNIÃO FEDERAL (AGU) | G41: FEDERAL | H41: Precatório | I41: Alimentar | J41: 45862
A42: 16278 | B42: 0000311-55.2025.5.19.0003 | D42: 11ª VARA DO TRABALHO DE MACEIÓ | E42: MARILUCIA RIBEIRO DE ANDRADE | F42: UNIÃO FEDERAL (AGU) | G42: FEDERAL | H42: Precatório | I42: Alimentar | J42: 45861
A43: 16278 | B43: 0000311-55.2025.5.19.0003 | D43: 11ª VARA DO TRABALHO DE MACEIÓ | E43: JOSE OLIVEIRA COSTA | F43: UNIÃO FEDERAL (AGU) | G43: FEDERAL | H43: Precatório | I43: Alimentar | J43: 45861
...
